    <gazebo>
        <plugin name="gazebo_ros_control" filename="libgazebo_ros_control.so">
            <robotNamespace>/mira</robotNamespace>
        </plugin>
    </gazebo>
    
    <joint name="roll_joint" type="revolute">
    	<parent link="base_link"/>
    	<child link="roll_M1_link"/>
        <origin xyz="0.0023 0 -0.0005" rpy="0 0 0"/>
        <limit lower="-0.2" upper="0.2" effort="0.1" velocity="0.005"/>
        <axis xyz="1 0 0"/>
	</joint>

    <transmission name="tran1">
        <type>transmission_interface/SimpleTransmission</type>
        <joint name="roll_joint">
            <hardwareInterface>EffortJointInterface</hardwareInterface>
        </joint>
        <actuator name="motor1">
            <hardwareInterface>EffortJointInterface</hardwareInterface>
            <mechanicalReduction>1</mechanicalReduction>
        </actuator>
    </transmission>